<?xml version="1.0" ?>
<!-- =================================================================================== -->
<!-- |    This document was autogenerated by xacro from centauro.urdf.xacro            | -->
<!-- |    EDITING THIS FILE BY HAND IS NOT RECOMMENDED                                 | -->
<!-- =================================================================================== -->
<robot name="centauro" xmlns:xacro="http://www.ros.org/wiki/xacro">
  <!-- /constants -->
  <!-- Here all arguments from launch file are evaluated to the final xacro poropeties.
     Also all the parameter dependencies are resolved-->
  <!-- ??? -->
  <!-- ??? -->
  <!-- Origin -->
  <!-- <xacro:property name="hip_yaw_lower" value="${[-2.827,-2.583, -2.583 ,-2.827]}"/>
<xacro:property name="hip_yaw_upper" value="${[ 2.583, 2.827,  2.827 , 2.583]}"/> -->
  <material name="grey">
    <color rgba="0.5 0.5 0.5 1"/>
  </material>
  <material name="dark_grey">
    <color rgba="0.3 0.3 0.3 1"/>
  </material>
  <material name="blue">
    <color rgba="0.0 0.2 0.3 1"/>
  </material>
  <material name="red">
    <color rgba="0.5 0.1 0.2 1"/>
  </material>
  <material name="black">
    <color rgba="0.0 0.0 0.0 1"/>
  </material>
  <!-- Here all arguments from launch file are evaluated to the final xacro poropeties.
     Also all the parameter dependencies are resolved-->
  <!-- load proper collision model -->
  <!-- load proper collision model -->
  <!-- load proper collision model -->
  <!-- load proper collision model -->
  <!-- Here all arguments from launch file are evaluated to the final xacro poropeties.
     Also all the parameter dependencies are resolved-->
  <!-- load proper collision model -->
  <!-- load proper collision model -->
  <!-- load proper collision model -->
  <!-- load proper collision model -->
  <!-- /macro legs -->
  <!-- /other files -->
  <!-- reference -->
  <!-- <link name="base_link"/>

<joint name="base_joint" type="fixed">
   <origin xyz="0 0 0"/>
   <parent link="base_link"/>
   <child link="world"/>
</joint>
-->
  <link name="world"/>
  <link name="pelvis">
    <inertial>
      <origin xyz="0.0013890071 -0.0015989148 0.063101012"/>
      <mass value="16.097574"/>
      <inertia ixx="0.23912627" ixy="-0.0050541269" ixz="-0.019746055" iyy="0.71430078" iyz="0.0002131204" izz="0.81870448"/>
    </inertial>
    <visual>
      <origin rpy="0.0 0.0 0.0" xyz="0.0 0 0.0"/>
      <geometry>
        <mesh filename="package://centauro/centauro_urdf/meshes/simplified/pelvis.stl" scale="0.001 0.001 0.001"/>
      </geometry>
    </visual>
    <collision>
      <origin rpy="0.0 0.0 0.0" xyz="0.0 0 0.0"/>
      <geometry>
        <mesh filename="package://centauro/centauro_urdf/meshes/convex_hull/pelvis.stl" scale="0.001 0.001 0.001"/>
      </geometry>
    </collision>
  </link>
  <link name="imu_link">
    <inertial>
      <mass value="0.0"/>
      <inertia ixx="0.0" ixy="0.0" ixz="0.0" iyy="0.0" iyz="0.0" izz="0.0"/>
    </inertial>
  </link>
  <joint name="imu_joint" type="fixed">
    <parent link="pelvis"/>
    <origin rpy="0.0 0.0 0.0" xyz="0.248316 0.0 0.015"/>
    <child link="imu_link"/>
  </joint>
  <joint name="reference" type="floating">
    <origin xyz="0.0 0.0 0.93445"/>
    <parent link="world"/>
    <child link="pelvis"/>
  </joint>
  <!-- /reference  -->
  <!-- /torso -->
  <!-- /arms -->
  <link name="hip1_1">
    <inertial>
      <origin xyz="0.010214199 -0.018348359 0.038090987"/>
      <mass value="1.9194403"/>
      <!-- org: 2 -->
      <inertia ixx="0.0047439572" ixy="0.0005747047" ixz="-0.0003784138" iyy="0.0040551878" iyz="0.0007407508" izz="0.0034146219"/>
      <!-- <inertia ixx="0.01" ixy="0.01" ixz="0.01" iyy="0.01" iyz="0.01" izz="0.01"/> -->
    </inertial>
    <visual>
      <origin rpy="0.0 0.0 4.06442490005" xyz="0.0 0.0 0.0"/>
      <geometry>
        <mesh filename="package://centauro/centauro_urdf/meshes/simplified/hip-yaw.stl" scale="0.001 0.001 0.001"/>
      </geometry>
      <material name="dark_grey"/>
    </visual>
    <collision>
      <origin rpy="0.0 0.0 4.06442490005" xyz="0.0 0.0 0.0"/>
      <geometry>
        <mesh filename="package://centauro/centauro_urdf/meshes/convex_hull/hip-yaw.stl" scale="0.001 0.001 0.001"/>
      </geometry>
    </collision>
  </link>
  <link name="hip2_1">
    <inertial>
      <origin xyz="2.57966e-05 0.1810266 0.085669756"/>
      <mass value="2.7264471"/>
      <!-- org: 4.5 -->
      <inertia ixx="0.04851869" ixy="-4.11894e-05" ixz="-1.68778e-05" iyy="0.004242055" iyz="0.0032243188" izz="0.04825583"/>
      <!-- <inertia ixx="0.01" ixy="0.01" ixz="0.01" iyy="0.01" iyz="0.01" izz="0.01"/> -->
    </inertial>
    <visual>
      <origin rpy="0.0 0.0 0.0" xyz="0.0 0.0 0.0"/>
      <geometry>
        <mesh filename="package://centauro/centauro_urdf/meshes/simplified/hip-pitch.stl" scale="0.001 0.001 0.001"/>
      </geometry>
    </visual>
    <collision>
      <origin rpy="0.0 0.0 0.0" xyz="0.0 0.0 0.0"/>
      <geometry>
        <mesh filename="package://centauro/centauro_urdf/meshes/convex_hull/hip-pitch.stl" scale="0.001 0.001 0.001"/>
      </geometry>
    </collision>
  </link>
  <link name="knee_1">
    <inertial>
      <origin xyz="0.10881667 0.0001089081 -0.022638996"/>
      <mass value="1.9356754"/>
      <!-- org: 3.5, foot un modeled-->
      <inertia ixx="0.0030534242" ixy="-4.22079e-05" ixz="0.0013679297" iyy="0.019603321" iyz="6.9941e-06" izz="0.019849817"/>
      <!--	<inertia ixx="0.01" ixy="0.01" ixz="0.01" iyy="0.01" iyz="0.01" izz="0.01"/>  -->
    </inertial>
    <visual>
      <origin rpy="0.0 0.0 0.0" xyz="0.0 0.0 0.0"/>
      <geometry>
        <mesh filename="package://centauro/centauro_urdf/meshes/simplified/knee.stl" scale="0.001 0.001 0.001"/>
      </geometry>
      <material name="dark_grey"/>
    </visual>
    <collision>
      <origin rpy="0.0 0.0 0.0" xyz="0.0 0.0 0.0"/>
      <geometry>
        <mesh filename="package://centauro/centauro_urdf/meshes/convex_hull/knee.stl" scale="0.001 0.001 0.001"/>
      </geometry>
    </collision>
  </link>
  <link name="ankle1_1">
    <inertial>
      <origin xyz="0.032137318 9.73572e-05 -0.0044222206"/>
      <mass value="1.2380744"/>
      <!-- org: 3.5, foot un modeled-->
      <inertia ixx="0.0015610452" ixy="3.30597e-05" ixz="-0.0001314174" iyy="0.0037423211" iyz="-2.12589e-05" izz="0.0038312442"/>
      <!--	<inertia ixx="0.01" ixy="0.01" ixz="0.01" iyy="0.01" iyz="0.01" izz="0.01"/>  -->
    </inertial>
    <visual>
      <origin rpy="0.0 0.0 0.0" xyz="0.0 0.0 0.0"/>
      <geometry>
        <mesh filename="package://centauro/centauro_urdf/meshes/simplified/ankle-pitch.stl" scale="0.001 0.001 0.001"/>
      </geometry>
    </visual>
    <collision>
      <origin rpy="0.0 0.0 0.0" xyz="0.0 0.0 0.0"/>
      <geometry>
        <mesh filename="package://centauro/centauro_urdf/meshes/convex_hull/ankle-pitch.stl" scale="0.001 0.001 0.001"/>
      </geometry>
    </collision>
  </link>
  <link name="ankle2_1">
    <inertial>
      <origin xyz="0.0004435803 0.0004389911 0.19392092"/>
      <mass value="1.1565926"/>
      <!-- org: 3.5, foot un modeled-->
      <inertia ixx="0.0049019475" ixy="4.3032e-06" ixz="3.46491e-05" iyy="0.0038724162" iyz="1.7099e-05" izz="0.0021783198"/>
    </inertial>
    <visual>
      <origin rpy="0.0 0.0 0.0" xyz="0.0 0.0 0.0"/>
      <geometry>
        <mesh filename="package://centauro/centauro_urdf/meshes/simplified/ankle-yaw.stl" scale="0.001 0.001 0.001"/>
      </geometry>
      <material name="dark_grey"/>
    </visual>
    <collision>
      <origin rpy="0.0 0.0 0.0" xyz="0.0 0.0 0.0"/>
      <geometry>
        <mesh filename="package://centauro/centauro_urdf/meshes/convex_hull/ankle-yaw.stl" scale="0.001 0.001 0.001"/>
      </geometry>
    </collision>
  </link>
  <link name="wheel_1">
    <inertial>
      <origin xyz="0.0 0.0 0.0024271906"/>
      <mass value="1.7289003"/>
      <!-- org: 3.5, foot un modeled-->
      <inertia ixx="0.0046864297" ixy="0.0" ixz="0.0" iyy="0.0046713489" iyz="0.0" izz="0.0053126029"/>
    </inertial>
    <visual>
      <origin rpy="0.0 0.0 0.0" xyz="0.0 0.0 0.0"/>
      <geometry>
        <mesh filename="package://centauro/centauro_urdf/meshes/simplified/wheel.stl" scale="0.001 0.001 0.001"/>
      </geometry>
      <material name="black"/>
    </visual>
    <collision>
      <origin rpy="0.0 0.0 0.0" xyz="0.0 0.0 0.0"/>
      <geometry>
        <mesh filename="package://centauro/centauro_urdf/meshes/convex_hull/wheel.stl" scale="0.001 0.001 0.001"/>
      </geometry>
    </collision>
  </link>
  <joint name="hip_yaw_1" type="revolute">
    <parent link="pelvis"/>
    <child link="hip1_1"/>
    <origin rpy="3.14159265359 0.0 0.461416123228" xyz="0.25 0.125 -0.0566"/>
    <axis xyz="0 0 1"/>
    <limit effort="304" lower="-2.03" upper="1.2" velocity="8.8"/>
  </joint>
  <joint name="hip_pitch_1" type="revolute">
    <parent link="hip1_1"/>
    <child link="hip2_1"/>
    <origin rpy="1.57079632679 0.0 0.46141612323" xyz="0.0 0.0 0.0625"/>
    <axis xyz="0 0 1"/>
    <limit effort="304" lower="-2.0226" upper="2.02748" velocity="8.8"/>
  </joint>
  <joint name="knee_pitch_1" type="revolute">
    <parent link="hip2_1"/>
    <child link="knee_1"/>
    <origin rpy="3.14159265359 0.0 1.57079632679" xyz="0.0 0.3 -0.0036"/>
    <axis xyz="0 0 1"/>
    <limit effort="304" lower="-2.4056" upper="2.3994" velocity="8.8"/>
  </joint>
  <joint name="ankle_pitch_1" type="revolute">
    <parent link="knee_1"/>
    <child link="ankle1_1"/>
    <origin rpy="3.14159265359 0.0 0.0" xyz="0.2 0.0 -0.10015"/>
    <axis xyz="0 0 1"/>
    <limit effort="147" lower="-2.4056" upper="2.3184" velocity="8.1"/>
  </joint>
  <joint name="ankle_yaw_1" type="revolute">
    <parent link="ankle1_1"/>
    <child link="ankle2_1"/>
    <origin rpy="1.57079632679 0.0 1.57079632679" xyz="0.0 0.0 0.0"/>
    <axis xyz="0 0 1"/>
    <limit effort="35" lower="-2.5626" upper="2.5384" velocity="20.0"/>
  </joint>
  <joint name="j_wheel_1" type="continuous">
    <parent link="ankle2_1"/>
    <child link="wheel_1"/>
    <origin rpy="1.57079632679 0.0 3.14159265359" xyz="0.0 0.00085 0.23735"/>
    <axis xyz="0 0 1"/>
    <limit effort="35" velocity="20.0"/>
  </joint>
  <transmission name="t_hip_yaw_1">
    <type> transmission_interface/SimpleTransmission</type>
    <joint name="hip_yaw_1">
      <hardwareInterface>hardware_interface/EffortJointInterface</hardwareInterface>
    </joint>
    <actuator name="motor_hip_yaw_1">
      <hardwareInterface>hardware_interface/EffortJointInterface</hardwareInterface>
      <machanicalReduction>1</machanicalReduction>
    </actuator>
    <robotNamespace>/centauro</robotNamespace>
  </transmission>
  <transmission name="t_hip_pitch_1">
    <type> transmission_interface/SimpleTransmission</type>
    <joint name="hip_pitch_1">
      <hardwareInterface>hardware_interface/EffortJointInterface</hardwareInterface>
    </joint>
    <actuator name="motor_hip_pitch_1">
      <hardwareInterface>hardware_interface/EffortJointInterface</hardwareInterface>
      <machanicalReduction>1</machanicalReduction>
    </actuator>
    <robotNamespace>/centauro</robotNamespace>
  </transmission>
  <transmission name="t_knee_pitch_1">
    <type> transmission_interface/SimpleTransmission</type>
    <joint name="knee_pitch_1">
      <hardwareInterface>hardware_interface/EffortJointInterface</hardwareInterface>
    </joint>
    <actuator name="motor_knee_pitch_1">
      <hardwareInterface>hardware_interface/EffortJointInterface</hardwareInterface>
      <machanicalReduction>1</machanicalReduction>
    </actuator>
    <robotNamespace>/centauro</robotNamespace>
  </transmission>
  <transmission name="t_ankle_pitch_1">
    <type> transmission_interface/SimpleTransmission</type>
    <joint name="ankle_pitch_1">
      <hardwareInterface>hardware_interface/EffortJointInterface</hardwareInterface>
    </joint>
    <actuator name="motor_ankle_pitch_1">
      <hardwareInterface>hardware_interface/EffortJointInterface</hardwareInterface>
      <machanicalReduction>1</machanicalReduction>
    </actuator>
    <robotNamespace>/centauro</robotNamespace>
  </transmission>
  <transmission name="t_ankle_yaw_1">
    <type> transmission_interface/SimpleTransmission</type>
    <joint name="ankle_yaw_1">
      <hardwareInterface>hardware_interface/EffortJointInterface</hardwareInterface>
    </joint>
    <actuator name="motor_ankle_yaw_1">
      <hardwareInterface>hardware_interface/EffortJointInterface</hardwareInterface>
      <machanicalReduction>1</machanicalReduction>
    </actuator>
    <robotNamespace>/centauro</robotNamespace>
  </transmission>
  <transmission name="t_j_wheel_1">
    <type> transmission_interface/SimpleTransmission</type>
    <joint name="j_wheel_1">
      <hardwareInterface>hardware_interface/EffortJointInterface</hardwareInterface>
    </joint>
    <actuator name="motor_j_wheel_1">
      <hardwareInterface>hardware_interface/EffortJointInterface</hardwareInterface>
      <machanicalReduction>1</machanicalReduction>
    </actuator>
    <robotNamespace>/centauro</robotNamespace>
  </transmission>
  <!-- /actuators -->
  <link name="hip1_2">
    <inertial>
      <origin xyz="0.010214199 0.018348359 0.038090987"/>
      <mass value="1.9194403"/>
      <!-- org: 2 -->
      <inertia ixx="0.0047439572" ixy="-0.0005747047" ixz="-0.0003784138" iyy="0.0040551878" iyz="-0.0007407508" izz="0.0034146219"/>
      <!-- <inertia ixx="0.01" ixy="0.01" ixz="0.01" iyy="0.01" iyz="0.01" izz="0.01"/> -->
    </inertial>
    <visual>
      <origin rpy="0.0 0.0 0.0" xyz="0.0 0.0 0.0"/>
      <geometry>
        <mesh filename="package://centauro/centauro_urdf/meshes/simplified/hip-yaw.stl" scale="0.001 0.001 0.001"/>
      </geometry>
      <material name="dark_grey"/>
    </visual>
    <collision>
      <origin rpy="0.0 0.0 0.0" xyz="0.0 0.0 0.0"/>
      <geometry>
        <mesh filename="package://centauro/centauro_urdf/meshes/convex_hull/hip-yaw.stl" scale="0.001 0.001 0.001"/>
      </geometry>
    </collision>
  </link>
  <link name="hip2_2">
    <inertial>
      <origin xyz="2.57966e-05 0.1810266 0.085669756"/>
      <mass value="2.7264471"/>
      <!-- org: 4.5 -->
      <inertia ixx="0.04851869" ixy="-4.11894e-05" ixz="-1.68778e-05" iyy="0.004242055" iyz="0.0032243188" izz="0.04825583"/>
      <!-- <inertia ixx="0.01" ixy="0.01" ixz="0.01" iyy="0.01" iyz="0.01" izz="0.01"/> -->
    </inertial>
    <visual>
      <origin rpy="0.0 0.0 0.0" xyz="0.0 0.0 0.0"/>
      <geometry>
        <mesh filename="package://centauro/centauro_urdf/meshes/simplified/hip-pitch.stl" scale="0.001 0.001 0.001"/>
      </geometry>
    </visual>
    <collision>
      <origin rpy="0.0 0.0 0.0" xyz="0.0 0.0 0.0"/>
      <geometry>
        <mesh filename="package://centauro/centauro_urdf/meshes/convex_hull/hip-pitch.stl" scale="0.001 0.001 0.001"/>
      </geometry>
    </collision>
  </link>
  <link name="knee_2">
    <inertial>
      <origin xyz="0.10881667 0.0001089081 -0.022638996"/>
      <mass value="1.9356754"/>
      <!-- org: 3.5, foot un modeled-->
      <inertia ixx="0.0030534242" ixy="-4.22079e-05" ixz="0.0013679297" iyy="0.019603321" iyz="6.9941e-06" izz="0.019849817"/>
      <!--	<inertia ixx="0.01" ixy="0.01" ixz="0.01" iyy="0.01" iyz="0.01" izz="0.01"/>  -->
    </inertial>
    <visual>
      <origin rpy="0.0 0.0 0.0" xyz="0.0 0.0 0.0"/>
      <geometry>
        <mesh filename="package://centauro/centauro_urdf/meshes/simplified/knee.stl" scale="0.001 0.001 0.001"/>
      </geometry>
      <material name="dark_grey"/>
    </visual>
    <collision>
      <origin rpy="0.0 0.0 0.0" xyz="0.0 0.0 0.0"/>
      <geometry>
        <mesh filename="package://centauro/centauro_urdf/meshes/convex_hull/knee.stl" scale="0.001 0.001 0.001"/>
      </geometry>
    </collision>
  </link>
  <link name="ankle1_2">
    <inertial>
      <origin xyz="0.032137318 9.73572e-05 -0.0044222206"/>
      <mass value="1.2380744"/>
      <!-- org: 3.5, foot un modeled-->
      <inertia ixx="0.0015610452" ixy="3.30597e-05" ixz="-0.0001314174" iyy="0.0037423211" iyz="-2.12589e-05" izz="0.0038312442"/>
      <!--	<inertia ixx="0.01" ixy="0.01" ixz="0.01" iyy="0.01" iyz="0.01" izz="0.01"/>  -->
    </inertial>
    <visual>
      <origin rpy="0.0 0.0 0.0" xyz="0.0 0.0 0.0"/>
      <geometry>
        <mesh filename="package://centauro/centauro_urdf/meshes/simplified/ankle-pitch.stl" scale="0.001 0.001 0.001"/>
      </geometry>
    </visual>
    <collision>
      <origin rpy="0.0 0.0 0.0" xyz="0.0 0.0 0.0"/>
      <geometry>
        <mesh filename="package://centauro/centauro_urdf/meshes/convex_hull/ankle-pitch.stl" scale="0.001 0.001 0.001"/>
      </geometry>
    </collision>
  </link>
  <link name="ankle2_2">
    <inertial>
      <origin xyz="0.0004435803 0.0004389911 0.19392092"/>
      <mass value="1.1565926"/>
      <!-- org: 3.5, foot un modeled-->
      <inertia ixx="0.0049019475" ixy="4.3032e-06" ixz="3.46491e-05" iyy="0.0038724162" iyz="1.7099e-05" izz="0.0021783198"/>
    </inertial>
    <visual>
      <origin rpy="0.0 0.0 0.0" xyz="0.0 0.0 0.0"/>
      <geometry>
        <mesh filename="package://centauro/centauro_urdf/meshes/simplified/ankle-yaw.stl" scale="0.001 0.001 0.001"/>
      </geometry>
      <material name="dark_grey"/>
    </visual>
    <collision>
      <origin rpy="0.0 0.0 0.0" xyz="0.0 0.0 0.0"/>
      <geometry>
        <mesh filename="package://centauro/centauro_urdf/meshes/convex_hull/ankle-yaw.stl" scale="0.001 0.001 0.001"/>
      </geometry>
    </collision>
  </link>
  <link name="wheel_2">
    <inertial>
      <origin xyz="0.0 0.0 0.0024271906"/>
      <mass value="1.7289003"/>
      <!-- org: 3.5, foot un modeled-->
      <inertia ixx="0.0046864297" ixy="0.0" ixz="0.0" iyy="0.0046713489" iyz="0.0" izz="0.0053126029"/>
    </inertial>
    <visual>
      <origin rpy="0.0 0.0 0.0" xyz="0.0 0.0 0.0"/>
      <geometry>
        <mesh filename="package://centauro/centauro_urdf/meshes/simplified/wheel.stl" scale="0.001 0.001 0.001"/>
      </geometry>
      <material name="black"/>
    </visual>
    <collision>
      <origin rpy="0.0 0.0 0.0" xyz="0.0 0.0 0.0"/>
      <geometry>
        <mesh filename="package://centauro/centauro_urdf/meshes/convex_hull/wheel.stl" scale="0.001 0.001 0.001"/>
      </geometry>
    </collision>
  </link>
  <joint name="hip_yaw_2" type="revolute">
    <parent link="pelvis"/>
    <child link="hip1_2"/>
    <origin rpy="3.14159265359 0.0 -0.461416123228" xyz="0.25 -0.125 -0.0566"/>
    <axis xyz="0 0 1"/>
    <limit effort="304" lower="-1.2" upper="2.03" velocity="8.8"/>
  </joint>
  <joint name="hip_pitch_2" type="revolute">
    <parent link="hip1_2"/>
    <child link="hip2_2"/>
    <origin rpy="1.57079632679 0.0 2.68017653036" xyz="0.0 0.0 0.0625"/>
    <axis xyz="0 0 1"/>
    <limit effort="304" lower="-2.0156" upper="2.0354" velocity="8.8"/>
  </joint>
  <joint name="knee_pitch_2" type="revolute">
    <parent link="hip2_2"/>
    <child link="knee_2"/>
    <origin rpy="3.14159265359 0.0 1.57079632679" xyz="0.0 0.3 -0.0036"/>
    <axis xyz="0 0 1"/>
    <limit effort="304" lower="-2.4006" upper="2.4034" velocity="8.8"/>
  </joint>
  <joint name="ankle_pitch_2" type="revolute">
    <parent link="knee_2"/>
    <child link="ankle1_2"/>
    <origin rpy="3.14159265359 0.0 0.0" xyz="0.2 0.0 -0.10015"/>
    <axis xyz="0 0 1"/>
    <limit effort="147" lower="-2.3266" upper="2.3914" velocity="8.1"/>
  </joint>
  <joint name="ankle_yaw_2" type="revolute">
    <parent link="ankle1_2"/>
    <child link="ankle2_2"/>
    <origin rpy="1.57079632679 0.0 1.57079632679" xyz="0.0 0.0 0.0"/>
    <axis xyz="0 0 1"/>
    <limit effort="35" lower="-2.5546" upper="2.5484" velocity="20.0"/>
  </joint>
  <joint name="j_wheel_2" type="continuous">
    <parent link="ankle2_2"/>
    <child link="wheel_2"/>
    <origin rpy="1.57079632679 0.0 3.14159265359" xyz="0.0 0.00085 0.23735"/>
    <axis xyz="0 0 1"/>
    <limit effort="35" velocity="20.0"/>
  </joint>
  <transmission name="t_hip_yaw_2">
    <type> transmission_interface/SimpleTransmission</type>
    <joint name="hip_yaw_2">
      <hardwareInterface>hardware_interface/EffortJointInterface</hardwareInterface>
    </joint>
    <actuator name="motor_hip_yaw_2">
      <hardwareInterface>hardware_interface/EffortJointInterface</hardwareInterface>
      <machanicalReduction>1</machanicalReduction>
    </actuator>
    <robotNamespace>/centauro</robotNamespace>
  </transmission>
  <transmission name="t_hip_pitch_2">
    <type> transmission_interface/SimpleTransmission</type>
    <joint name="hip_pitch_2">
      <hardwareInterface>hardware_interface/EffortJointInterface</hardwareInterface>
    </joint>
    <actuator name="motor_hip_pitch_2">
      <hardwareInterface>hardware_interface/EffortJointInterface</hardwareInterface>
      <machanicalReduction>1</machanicalReduction>
    </actuator>
    <robotNamespace>/centauro</robotNamespace>
  </transmission>
  <transmission name="t_knee_pitch_2">
    <type> transmission_interface/SimpleTransmission</type>
    <joint name="knee_pitch_2">
      <hardwareInterface>hardware_interface/EffortJointInterface</hardwareInterface>
    </joint>
    <actuator name="motor_knee_pitch_2">
      <hardwareInterface>hardware_interface/EffortJointInterface</hardwareInterface>
      <machanicalReduction>1</machanicalReduction>
    </actuator>
    <robotNamespace>/centauro</robotNamespace>
  </transmission>
  <transmission name="t_ankle_pitch_2">
    <type> transmission_interface/SimpleTransmission</type>
    <joint name="ankle_pitch_2">
      <hardwareInterface>hardware_interface/EffortJointInterface</hardwareInterface>
    </joint>
    <actuator name="motor_ankle_pitch_2">
      <hardwareInterface>hardware_interface/EffortJointInterface</hardwareInterface>
      <machanicalReduction>1</machanicalReduction>
    </actuator>
    <robotNamespace>/centauro</robotNamespace>
  </transmission>
  <transmission name="t_ankle_yaw_2">
    <type> transmission_interface/SimpleTransmission</type>
    <joint name="ankle_yaw_2">
      <hardwareInterface>hardware_interface/EffortJointInterface</hardwareInterface>
    </joint>
    <actuator name="motor_ankle_yaw_2">
      <hardwareInterface>hardware_interface/EffortJointInterface</hardwareInterface>
      <machanicalReduction>1</machanicalReduction>
    </actuator>
    <robotNamespace>/centauro</robotNamespace>
  </transmission>
  <transmission name="t_j_wheel_2">
    <type> transmission_interface/SimpleTransmission</type>
    <joint name="j_wheel_2">
      <hardwareInterface>hardware_interface/EffortJointInterface</hardwareInterface>
    </joint>
    <actuator name="motor_j_wheel_2">
      <hardwareInterface>hardware_interface/EffortJointInterface</hardwareInterface>
      <machanicalReduction>1</machanicalReduction>
    </actuator>
    <robotNamespace>/centauro</robotNamespace>
  </transmission>
  <!-- /actuators -->
  <link name="hip1_3">
    <inertial>
      <origin xyz="0.010214199 0.018348359 0.038090987"/>
      <mass value="1.9194403"/>
      <!-- org: 2 -->
      <inertia ixx="0.0047439572" ixy="-0.0005747047" ixz="-0.0003784138" iyy="0.0040551878" iyz="-0.0007407508" izz="0.0034146219"/>
      <!-- <inertia ixx="0.01" ixy="0.01" ixz="0.01" iyy="0.01" iyz="0.01" izz="0.01"/> -->
    </inertial>
    <visual>
      <origin rpy="0.0 0.0 0.0" xyz="0.0 0.0 0.0"/>
      <geometry>
        <mesh filename="package://centauro/centauro_urdf/meshes/simplified/hip-yaw.stl" scale="0.001 0.001 0.001"/>
      </geometry>
      <material name="dark_grey"/>
    </visual>
    <collision>
      <origin rpy="0.0 0.0 0.0" xyz="0.0 0.0 0.0"/>
      <geometry>
        <mesh filename="package://centauro/centauro_urdf/meshes/convex_hull/hip-yaw.stl" scale="0.001 0.001 0.001"/>
      </geometry>
    </collision>
  </link>
  <link name="hip2_3">
    <inertial>
      <origin xyz="2.57966e-05 0.1810266 0.085669756"/>
      <mass value="2.7264471"/>
      <!-- org: 4.5 -->
      <inertia ixx="0.04851869" ixy="-4.11894e-05" ixz="-1.68778e-05" iyy="0.004242055" iyz="0.0032243188" izz="0.04825583"/>
      <!-- <inertia ixx="0.01" ixy="0.01" ixz="0.01" iyy="0.01" iyz="0.01" izz="0.01"/> -->
    </inertial>
    <visual>
      <origin rpy="0.0 0.0 0.0" xyz="0.0 0.0 0.0"/>
      <geometry>
        <mesh filename="package://centauro/centauro_urdf/meshes/simplified/hip-pitch.stl" scale="0.001 0.001 0.001"/>
      </geometry>
    </visual>
    <collision>
      <origin rpy="0.0 0.0 0.0" xyz="0.0 0.0 0.0"/>
      <geometry>
        <mesh filename="package://centauro/centauro_urdf/meshes/convex_hull/hip-pitch.stl" scale="0.001 0.001 0.001"/>
      </geometry>
    </collision>
  </link>
  <link name="knee_3">
    <inertial>
      <origin xyz="0.10881667 0.0001089081 -0.022638996"/>
      <mass value="1.9356754"/>
      <!-- org: 3.5, foot un modeled-->
      <inertia ixx="0.0030534242" ixy="-4.22079e-05" ixz="0.0013679297" iyy="0.019603321" iyz="6.9941e-06" izz="0.019849817"/>
      <!--	<inertia ixx="0.01" ixy="0.01" ixz="0.01" iyy="0.01" iyz="0.01" izz="0.01"/>  -->
    </inertial>
    <visual>
      <origin rpy="0.0 0.0 0.0" xyz="0.0 0.0 0.0"/>
      <geometry>
        <mesh filename="package://centauro/centauro_urdf/meshes/simplified/knee.stl" scale="0.001 0.001 0.001"/>
      </geometry>
      <material name="dark_grey"/>
    </visual>
    <collision>
      <origin rpy="0.0 0.0 0.0" xyz="0.0 0.0 0.0"/>
      <geometry>
        <mesh filename="package://centauro/centauro_urdf/meshes/convex_hull/knee.stl" scale="0.001 0.001 0.001"/>
      </geometry>
    </collision>
  </link>
  <link name="ankle1_3">
    <inertial>
      <origin xyz="0.032137318 9.73572e-05 -0.0044222206"/>
      <mass value="1.2380744"/>
      <!-- org: 3.5, foot un modeled-->
      <inertia ixx="0.0015610452" ixy="3.30597e-05" ixz="-0.0001314174" iyy="0.0037423211" iyz="-2.12589e-05" izz="0.0038312442"/>
      <!--	<inertia ixx="0.01" ixy="0.01" ixz="0.01" iyy="0.01" iyz="0.01" izz="0.01"/>  -->
    </inertial>
    <visual>
      <origin rpy="0.0 0.0 0.0" xyz="0.0 0.0 0.0"/>
      <geometry>
        <mesh filename="package://centauro/centauro_urdf/meshes/simplified/ankle-pitch.stl" scale="0.001 0.001 0.001"/>
      </geometry>
    </visual>
    <collision>
      <origin rpy="0.0 0.0 0.0" xyz="0.0 0.0 0.0"/>
      <geometry>
        <mesh filename="package://centauro/centauro_urdf/meshes/convex_hull/ankle-pitch.stl" scale="0.001 0.001 0.001"/>
      </geometry>
    </collision>
  </link>
  <link name="ankle2_3">
    <inertial>
      <origin xyz="0.0004435803 0.0004389911 0.19392092"/>
      <mass value="1.1565926"/>
      <!-- org: 3.5, foot un modeled-->
      <inertia ixx="0.0049019475" ixy="4.3032e-06" ixz="3.46491e-05" iyy="0.0038724162" iyz="1.7099e-05" izz="0.0021783198"/>
    </inertial>
    <visual>
      <origin rpy="0.0 0.0 0.0" xyz="0.0 0.0 0.0"/>
      <geometry>
        <mesh filename="package://centauro/centauro_urdf/meshes/simplified/ankle-yaw.stl" scale="0.001 0.001 0.001"/>
      </geometry>
      <material name="dark_grey"/>
    </visual>
    <collision>
      <origin rpy="0.0 0.0 0.0" xyz="0.0 0.0 0.0"/>
      <geometry>
        <mesh filename="package://centauro/centauro_urdf/meshes/convex_hull/ankle-yaw.stl" scale="0.001 0.001 0.001"/>
      </geometry>
    </collision>
  </link>
  <link name="wheel_3">
    <inertial>
      <origin xyz="0.0 0.0 0.0024271906"/>
      <mass value="1.7289003"/>
      <!-- org: 3.5, foot un modeled-->
      <inertia ixx="0.0046864297" ixy="0.0" ixz="0.0" iyy="0.0046713489" iyz="0.0" izz="0.0053126029"/>
    </inertial>
    <visual>
      <origin rpy="0.0 0.0 0.0" xyz="0.0 0.0 0.0"/>
      <geometry>
        <mesh filename="package://centauro/centauro_urdf/meshes/simplified/wheel.stl" scale="0.001 0.001 0.001"/>
      </geometry>
      <material name="black"/>
    </visual>
    <collision>
      <origin rpy="0.0 0.0 0.0" xyz="0.0 0.0 0.0"/>
      <geometry>
        <mesh filename="package://centauro/centauro_urdf/meshes/convex_hull/wheel.stl" scale="0.001 0.001 0.001"/>
      </geometry>
    </collision>
  </link>
  <joint name="hip_yaw_3" type="revolute">
    <parent link="pelvis"/>
    <child link="hip1_3"/>
    <origin rpy="3.14159265359 0.0 2.68017653036" xyz="-0.25 0.125 -0.0566"/>
    <axis xyz="0 0 1"/>
    <limit effort="304" lower="-1.2" upper="2.03" velocity="8.8"/>
  </joint>
  <joint name="hip_pitch_3" type="revolute">
    <parent link="hip1_3"/>
    <child link="hip2_3"/>
    <origin rpy="1.57079632679 0.0 2.68017653036" xyz="0.0 0.0 0.0625"/>
    <axis xyz="0 0 1"/>
    <limit effort="304" lower="-2.0126" upper="2.0384" velocity="8.8"/>
  </joint>
  <joint name="knee_pitch_3" type="revolute">
    <parent link="hip2_3"/>
    <child link="knee_3"/>
    <origin rpy="3.14159265359 0.0 1.57079632679" xyz="0.0 0.3 -0.0036"/>
    <axis xyz="0 0 1"/>
    <limit effort="304" lower="-2.4056" upper="2.4064" velocity="8.8"/>
  </joint>
  <joint name="ankle_pitch_3" type="revolute">
    <parent link="knee_3"/>
    <child link="ankle1_3"/>
    <origin rpy="3.14159265359 0.0 0.0" xyz="0.2 0.0 -0.10015"/>
    <axis xyz="0 0 1"/>
    <limit effort="147" lower="-2.4696" upper="2.4464" velocity="8.1"/>
  </joint>
  <joint name="ankle_yaw_3" type="revolute">
    <parent link="ankle1_3"/>
    <child link="ankle2_3"/>
    <origin rpy="1.57079632679 0.0 1.57079632679" xyz="0.0 0.0 0.0"/>
    <axis xyz="0 0 1"/>
    <limit effort="35" lower="-2.5606" upper="2.5454" velocity="20.0"/>
  </joint>
  <joint name="j_wheel_3" type="continuous">
    <parent link="ankle2_3"/>
    <child link="wheel_3"/>
    <origin rpy="1.57079632679 0.0 3.14159265359" xyz="0.0 0.00085 0.23735"/>
    <axis xyz="0 0 1"/>
    <limit effort="35" velocity="20.0"/>
  </joint>
  <transmission name="t_hip_yaw_3">
    <type> transmission_interface/SimpleTransmission</type>
    <joint name="hip_yaw_3">
      <hardwareInterface>hardware_interface/EffortJointInterface</hardwareInterface>
    </joint>
    <actuator name="motor_hip_yaw_3">
      <hardwareInterface>hardware_interface/EffortJointInterface</hardwareInterface>
      <machanicalReduction>1</machanicalReduction>
    </actuator>
    <robotNamespace>/centauro</robotNamespace>
  </transmission>
  <transmission name="t_hip_pitch_3">
    <type> transmission_interface/SimpleTransmission</type>
    <joint name="hip_pitch_3">
      <hardwareInterface>hardware_interface/EffortJointInterface</hardwareInterface>
    </joint>
    <actuator name="motor_hip_pitch_3">
      <hardwareInterface>hardware_interface/EffortJointInterface</hardwareInterface>
      <machanicalReduction>1</machanicalReduction>
    </actuator>
    <robotNamespace>/centauro</robotNamespace>
  </transmission>
  <transmission name="t_knee_pitch_3">
    <type> transmission_interface/SimpleTransmission</type>
    <joint name="knee_pitch_3">
      <hardwareInterface>hardware_interface/EffortJointInterface</hardwareInterface>
    </joint>
    <actuator name="motor_knee_pitch_3">
      <hardwareInterface>hardware_interface/EffortJointInterface</hardwareInterface>
      <machanicalReduction>1</machanicalReduction>
    </actuator>
    <robotNamespace>/centauro</robotNamespace>
  </transmission>
  <transmission name="t_ankle_pitch_3">
    <type> transmission_interface/SimpleTransmission</type>
    <joint name="ankle_pitch_3">
      <hardwareInterface>hardware_interface/EffortJointInterface</hardwareInterface>
    </joint>
    <actuator name="motor_ankle_pitch_3">
      <hardwareInterface>hardware_interface/EffortJointInterface</hardwareInterface>
      <machanicalReduction>1</machanicalReduction>
    </actuator>
    <robotNamespace>/centauro</robotNamespace>
  </transmission>
  <transmission name="t_ankle_yaw_3">
    <type> transmission_interface/SimpleTransmission</type>
    <joint name="ankle_yaw_3">
      <hardwareInterface>hardware_interface/EffortJointInterface</hardwareInterface>
    </joint>
    <actuator name="motor_ankle_yaw_3">
      <hardwareInterface>hardware_interface/EffortJointInterface</hardwareInterface>
      <machanicalReduction>1</machanicalReduction>
    </actuator>
    <robotNamespace>/centauro</robotNamespace>
  </transmission>
  <transmission name="t_j_wheel_3">
    <type> transmission_interface/SimpleTransmission</type>
    <joint name="j_wheel_3">
      <hardwareInterface>hardware_interface/EffortJointInterface</hardwareInterface>
    </joint>
    <actuator name="motor_j_wheel_3">
      <hardwareInterface>hardware_interface/EffortJointInterface</hardwareInterface>
      <machanicalReduction>1</machanicalReduction>
    </actuator>
    <robotNamespace>/centauro</robotNamespace>
  </transmission>
  <!-- /actuators -->
  <link name="hip1_4">
    <inertial>
      <origin xyz="0.010214199 -0.018348359 0.038090987"/>
      <mass value="1.9194403"/>
      <!-- org: 2 -->
      <inertia ixx="0.0047439572" ixy="0.0005747047" ixz="-0.0003784138" iyy="0.0040551878" iyz="0.0007407508" izz="0.0034146219"/>
      <!-- <inertia ixx="0.01" ixy="0.01" ixz="0.01" iyy="0.01" iyz="0.01" izz="0.01"/> -->
    </inertial>
    <visual>
      <origin rpy="0.0 0.0 4.06442490005" xyz="0.0 0.0 0.0"/>
      <geometry>
        <mesh filename="package://centauro/centauro_urdf/meshes/simplified/hip-yaw.stl" scale="0.001 0.001 0.001"/>
      </geometry>
      <material name="dark_grey"/>
    </visual>
    <collision>
      <origin rpy="0.0 0.0 4.06442490005" xyz="0.0 0.0 0.0"/>
      <geometry>
        <mesh filename="package://centauro/centauro_urdf/meshes/convex_hull/hip-yaw.stl" scale="0.001 0.001 0.001"/>
      </geometry>
    </collision>
  </link>
  <link name="hip2_4">
    <inertial>
      <origin xyz="2.57966e-05 0.1810266 0.085669756"/>
      <mass value="2.7264471"/>
      <!-- org: 4.5 -->
      <inertia ixx="0.04851869" ixy="-4.11894e-05" ixz="-1.68778e-05" iyy="0.004242055" iyz="0.0032243188" izz="0.04825583"/>
      <!-- <inertia ixx="0.01" ixy="0.01" ixz="0.01" iyy="0.01" iyz="0.01" izz="0.01"/> -->
    </inertial>
    <visual>
      <origin rpy="0.0 0.0 0.0" xyz="0.0 0.0 0.0"/>
      <geometry>
        <mesh filename="package://centauro/centauro_urdf/meshes/simplified/hip-pitch.stl" scale="0.001 0.001 0.001"/>
      </geometry>
    </visual>
    <collision>
      <origin rpy="0.0 0.0 0.0" xyz="0.0 0.0 0.0"/>
      <geometry>
        <mesh filename="package://centauro/centauro_urdf/meshes/convex_hull/hip-pitch.stl" scale="0.001 0.001 0.001"/>
      </geometry>
    </collision>
  </link>
  <link name="knee_4">
    <inertial>
      <origin xyz="0.10881667 0.0001089081 -0.022638996"/>
      <mass value="1.9356754"/>
      <!-- org: 3.5, foot un modeled-->
      <inertia ixx="0.0030534242" ixy="-4.22079e-05" ixz="0.0013679297" iyy="0.019603321" iyz="6.9941e-06" izz="0.019849817"/>
      <!--	<inertia ixx="0.01" ixy="0.01" ixz="0.01" iyy="0.01" iyz="0.01" izz="0.01"/>  -->
    </inertial>
    <visual>
      <origin rpy="0.0 0.0 0.0" xyz="0.0 0.0 0.0"/>
      <geometry>
        <mesh filename="package://centauro/centauro_urdf/meshes/simplified/knee.stl" scale="0.001 0.001 0.001"/>
      </geometry>
      <material name="dark_grey"/>
    </visual>
    <collision>
      <origin rpy="0.0 0.0 0.0" xyz="0.0 0.0 0.0"/>
      <geometry>
        <mesh filename="package://centauro/centauro_urdf/meshes/convex_hull/knee.stl" scale="0.001 0.001 0.001"/>
      </geometry>
    </collision>
  </link>
  <link name="ankle1_4">
    <inertial>
      <origin xyz="0.032137318 9.73572e-05 -0.0044222206"/>
      <mass value="1.2380744"/>
      <!-- org: 3.5, foot un modeled-->
      <inertia ixx="0.0015610452" ixy="3.30597e-05" ixz="-0.0001314174" iyy="0.0037423211" iyz="-2.12589e-05" izz="0.0038312442"/>
      <!--	<inertia ixx="0.01" ixy="0.01" ixz="0.01" iyy="0.01" iyz="0.01" izz="0.01"/>  -->
    </inertial>
    <visual>
      <origin rpy="0.0 0.0 0.0" xyz="0.0 0.0 0.0"/>
      <geometry>
        <mesh filename="package://centauro/centauro_urdf/meshes/simplified/ankle-pitch.stl" scale="0.001 0.001 0.001"/>
      </geometry>
    </visual>
    <collision>
      <origin rpy="0.0 0.0 0.0" xyz="0.0 0.0 0.0"/>
      <geometry>
        <mesh filename="package://centauro/centauro_urdf/meshes/convex_hull/ankle-pitch.stl" scale="0.001 0.001 0.001"/>
      </geometry>
    </collision>
  </link>
  <link name="ankle2_4">
    <inertial>
      <origin xyz="0.0004435803 0.0004389911 0.19392092"/>
      <mass value="1.1565926"/>
      <!-- org: 3.5, foot un modeled-->
      <inertia ixx="0.0049019475" ixy="4.3032e-06" ixz="3.46491e-05" iyy="0.0038724162" iyz="1.7099e-05" izz="0.0021783198"/>
    </inertial>
    <visual>
      <origin rpy="0.0 0.0 0.0" xyz="0.0 0.0 0.0"/>
      <geometry>
        <mesh filename="package://centauro/centauro_urdf/meshes/simplified/ankle-yaw.stl" scale="0.001 0.001 0.001"/>
      </geometry>
      <material name="dark_grey"/>
    </visual>
    <collision>
      <origin rpy="0.0 0.0 0.0" xyz="0.0 0.0 0.0"/>
      <geometry>
        <mesh filename="package://centauro/centauro_urdf/meshes/convex_hull/ankle-yaw.stl" scale="0.001 0.001 0.001"/>
      </geometry>
    </collision>
  </link>
  <link name="wheel_4">
    <inertial>
      <origin xyz="0.0 0.0 0.0024271906"/>
      <mass value="1.7289003"/>
      <!-- org: 3.5, foot un modeled-->
      <inertia ixx="0.0046864297" ixy="0.0" ixz="0.0" iyy="0.0046713489" iyz="0.0" izz="0.0053126029"/>
    </inertial>
    <visual>
      <origin rpy="0.0 0.0 0.0" xyz="0.0 0.0 0.0"/>
      <geometry>
        <mesh filename="package://centauro/centauro_urdf/meshes/simplified/wheel.stl" scale="0.001 0.001 0.001"/>
      </geometry>
      <material name="black"/>
    </visual>
    <collision>
      <origin rpy="0.0 0.0 0.0" xyz="0.0 0.0 0.0"/>
      <geometry>
        <mesh filename="package://centauro/centauro_urdf/meshes/convex_hull/wheel.stl" scale="0.001 0.001 0.001"/>
      </geometry>
    </collision>
  </link>
  <joint name="hip_yaw_4" type="revolute">
    <parent link="pelvis"/>
    <child link="hip1_4"/>
    <origin rpy="3.14159265359 0.0 3.60300877682" xyz="-0.25 -0.125 -0.0566"/>
    <axis xyz="0 0 1"/>
    <limit effort="304" lower="-2.03" upper="1.2" velocity="8.8"/>
  </joint>
  <joint name="hip_pitch_4" type="revolute">
    <parent link="hip1_4"/>
    <child link="hip2_4"/>
    <origin rpy="1.57079632679 0.0 0.46141612323" xyz="0.0 0.0 0.0625"/>
    <axis xyz="0 0 1"/>
    <limit effort="304" lower="-2.0326" upper="2.0524" velocity="8.8"/>
  </joint>
  <joint name="knee_pitch_4" type="revolute">
    <parent link="hip2_4"/>
    <child link="knee_4"/>
    <origin rpy="3.14159265359 0.0 1.57079632679" xyz="0.0 0.3 -0.0036"/>
    <axis xyz="0 0 1"/>
    <limit effort="304" lower="-2.4176" upper="2.3884" velocity="8.8"/>
  </joint>
  <joint name="ankle_pitch_4" type="revolute">
    <parent link="knee_4"/>
    <child link="ankle1_4"/>
    <origin rpy="3.14159265359 0.0 0.0" xyz="0.2 0.0 -0.10015"/>
    <axis xyz="0 0 1"/>
    <limit effort="147" lower="-2.3426" upper="2.3934" velocity="8.1"/>
  </joint>
  <joint name="ankle_yaw_4" type="revolute">
    <parent link="ankle1_4"/>
    <child link="ankle2_4"/>
    <origin rpy="1.57079632679 0.0 1.57079632679" xyz="0.0 0.0 0.0"/>
    <axis xyz="0 0 1"/>
    <limit effort="35" lower="-2.6046" upper="2.5514" velocity="20.0"/>
  </joint>
  <joint name="j_wheel_4" type="continuous">
    <parent link="ankle2_4"/>
    <child link="wheel_4"/>
    <origin rpy="1.57079632679 0.0 3.14159265359" xyz="0.0 0.00085 0.23735"/>
    <axis xyz="0 0 1"/>
    <limit effort="35" velocity="20.0"/>
  </joint>
  <transmission name="t_hip_yaw_4">
    <type> transmission_interface/SimpleTransmission</type>
    <joint name="hip_yaw_4">
      <hardwareInterface>hardware_interface/EffortJointInterface</hardwareInterface>
    </joint>
    <actuator name="motor_hip_yaw_4">
      <hardwareInterface>hardware_interface/EffortJointInterface</hardwareInterface>
      <machanicalReduction>1</machanicalReduction>
    </actuator>
    <robotNamespace>/centauro</robotNamespace>
  </transmission>
  <transmission name="t_hip_pitch_4">
    <type> transmission_interface/SimpleTransmission</type>
    <joint name="hip_pitch_4">
      <hardwareInterface>hardware_interface/EffortJointInterface</hardwareInterface>
    </joint>
    <actuator name="motor_hip_pitch_4">
      <hardwareInterface>hardware_interface/EffortJointInterface</hardwareInterface>
      <machanicalReduction>1</machanicalReduction>
    </actuator>
    <robotNamespace>/centauro</robotNamespace>
  </transmission>
  <transmission name="t_knee_pitch_4">
    <type> transmission_interface/SimpleTransmission</type>
    <joint name="knee_pitch_4">
      <hardwareInterface>hardware_interface/EffortJointInterface</hardwareInterface>
    </joint>
    <actuator name="motor_knee_pitch_4">
      <hardwareInterface>hardware_interface/EffortJointInterface</hardwareInterface>
      <machanicalReduction>1</machanicalReduction>
    </actuator>
    <robotNamespace>/centauro</robotNamespace>
  </transmission>
  <transmission name="t_ankle_pitch_4">
    <type> transmission_interface/SimpleTransmission</type>
    <joint name="ankle_pitch_4">
      <hardwareInterface>hardware_interface/EffortJointInterface</hardwareInterface>
    </joint>
    <actuator name="motor_ankle_pitch_4">
      <hardwareInterface>hardware_interface/EffortJointInterface</hardwareInterface>
      <machanicalReduction>1</machanicalReduction>
    </actuator>
    <robotNamespace>/centauro</robotNamespace>
  </transmission>
  <transmission name="t_ankle_yaw_4">
    <type> transmission_interface/SimpleTransmission</type>
    <joint name="ankle_yaw_4">
      <hardwareInterface>hardware_interface/EffortJointInterface</hardwareInterface>
    </joint>
    <actuator name="motor_ankle_yaw_4">
      <hardwareInterface>hardware_interface/EffortJointInterface</hardwareInterface>
      <machanicalReduction>1</machanicalReduction>
    </actuator>
    <robotNamespace>/centauro</robotNamespace>
  </transmission>
  <transmission name="t_j_wheel_4">
    <type> transmission_interface/SimpleTransmission</type>
    <joint name="j_wheel_4">
      <hardwareInterface>hardware_interface/EffortJointInterface</hardwareInterface>
    </joint>
    <actuator name="motor_j_wheel_4">
      <hardwareInterface>hardware_interface/EffortJointInterface</hardwareInterface>
      <machanicalReduction>1</machanicalReduction>
    </actuator>
    <robotNamespace>/centauro</robotNamespace>
  </transmission>
  <!-- /actuators -->
  <!-- /legs -->
</robot>
