<?xml version="1.0" ?>
<!-- =================================================================================== -->
<!-- |    This document was autogenerated by xacro from centauro.urdf.xacro            | -->
<!-- |    EDITING THIS FILE BY HAND IS NOT RECOMMENDED                                 | -->
<!-- =================================================================================== -->
<robot name="centauro" xmlns:xacro="http://www.ros.org/wiki/xacro">
  <!-- /constants -->
  <!-- Here all arguments from launch file are evaluated to the final xacro poropeties.
     Also all the parameter dependencies are resolved-->
  <material name="grey">
    <color rgba="0.5 0.5 0.5 1"/>
  </material>
  <material name="dark_grey">
    <color rgba="0.3 0.3 0.3 1"/>
  </material>
  <material name="blue">
    <color rgba="0.0 0.2 0.3 1"/>
  </material>
  <material name="red">
    <color rgba="0.5 0.1 0.2 1"/>
  </material>
  <material name="black">
    <color rgba="0.0 0.0 0.0 1"/>
  </material>
  <!-- Here all arguments from launch file are evaluated to the final xacro poropeties.
     Also all the parameter dependencies are resolved-->
  <!-- load proper collision model -->
  <!-- load proper collision model -->
  <!-- load proper collision model -->
  <!-- load proper collision model -->
  <!-- load proper collision model -->
  <!-- Here all arguments from launch file are evaluated to the final xacro poropeties.
     Also all the parameter dependencies are resolved-->
  <!-- load proper collision model -->
  <!-- load proper collision model -->
  <!-- load proper collision model -->
  <!-- load proper collision model -->
  <!-- load proper collision model -->
  <!-- /macro arms -->
  <!-- /other files -->
  <!-- reference -->
  <!-- <link name="base_link"/>

<joint name="base_joint" type="fixed">
   <origin xyz="0 0 0"/>
   <parent link="base_link"/>
   <child link="world"/>
</joint>
-->
  <link name="world"/>
  <link name="pelvis"/>
  <joint name="reference" type="fixed">
    <origin xyz="0.0 0.0 0.93445"/>
    <parent link="world"/>
    <child link="pelvis"/>
  </joint>
  <!-- /reference  -->
  <!-- torso links -->
  <link name="torso_2">
    <inertial>
      <origin xyz="0.0064454169 0.0021390093 0.14302095"/>
      <mass value="6.1886404"/>
      <inertia ixx="0.063643392" ixy="8.939e-05" ixz="-0.00086873" iyy="0.02680235" iyz="-4.657e-05" izz="0.04743015"/>
    </inertial>
    <visual>
      <origin rpy="0.0 0.0 0.0" xyz="0.0 0 0.0"/>
      <geometry>
        <mesh filename="package://centauro/centauro_urdf/meshes/simplified/link1.stl" scale="0.001 0.001 0.001"/>
      </geometry>
    </visual>
    <collision>
      <origin rpy="0.0 0.0 0.0" xyz="0.0 0 0.0"/>
      <geometry>
        <mesh filename="package://centauro/centauro_urdf/meshes/convex_hull/link1.stl" scale="0.001 0.001 0.001"/>
      </geometry>
    </collision>
  </link>
  <!-- /torso links -->
  <!-- torso joints -->
  <joint name="torso_yaw" type="revolute">
    <parent link="world"/>
    <origin xyz="0.2 0.0 1.19045"/>
    <child link="torso_2"/>
    <axis xyz="0 0 1"/>
    <limit effort="147" lower="-2.618" upper="2.618" velocity="5.7"/>
    <!-- TODO -->
  </joint>
  <!-- /torso joints -->
  <transmission name="t_torso_yaw">
    <type> transmission_interface/SimpleTransmission</type>
    <joint name="torso_yaw">
      <hardwareInterface>hardware_interface/EffortJointInterface</hardwareInterface>
    </joint>
    <actuator name="motor_torso_yaw">
      <hardwareInterface>hardware_interface/EffortJointInterface</hardwareInterface>
      <machanicalReduction>1</machanicalReduction>
    </actuator>
    <robotNamespace>/centauro</robotNamespace>
  </transmission>
  <!-- /torso actuators -->
  <!-- head links -->
  <link name="neck_1">
    <inertial>
      <origin xyz="0.040479674 0.021377573 -0.014595112"/>
      <mass value="0.33878686"/>
      <inertia ixx="0.0003718568" ixy="-9.42983e-05" ixz="-2.80644e-05" iyy="0.0001886879" iyz="-1.54534e-05" izz="0.0005023443"/>
    </inertial>
    <visual>
      <origin rpy="0.0 0.0 0.0" xyz="0.0 0 0.0"/>
      <geometry>
        <mesh filename="package://centauro/centauro_urdf/meshes/simplified/neck_yaw.stl" scale="0.001 0.001 0.001"/>
      </geometry>
    </visual>
    <collision>
      <origin rpy="0.0 0.0 0.0" xyz="0.0 0 0.0"/>
      <geometry>
        <mesh filename="package://centauro/centauro_urdf/meshes/convex_hull/neck_yaw.stl" scale="0.001 0.001 0.001"/>
      </geometry>
    </collision>
  </link>
  <link name="neck_2">
    <inertial>
      <origin xyz="0.048466918 -0.059852318 -0.0085314894"/>
      <mass value="0.78526942"/>
      <inertia ixx="0.0004682345" ixy="-1.05438e-05" ixz="7.24398e-05" iyy="0.0002635246" iyz="1.6904e-06" izz="0.0003763351"/>
    </inertial>
    <visual>
      <origin rpy="0.0 0.0 0.0" xyz="0.0 0 0.0"/>
      <geometry>
        <mesh filename="package://centauro/centauro_urdf/meshes/simplified/neck_pitch.stl" scale="0.001 0.001 0.001"/>
      </geometry>
    </visual>
    <collision>
      <origin rpy="0.0 0.0 0.0" xyz="0.0 0 0.0"/>
      <geometry>
        <mesh filename="package://centauro/centauro_urdf/meshes/convex_hull/neck_pitch.stl" scale="0.001 0.001 0.001"/>
      </geometry>
    </collision>
  </link>
  <link name="neck_3">
    <inertial>
      <origin xyz="0.048466918 -0.059852318 -0.0085314894"/>
      <mass value="0.78526942"/>
      <inertia ixx="0.0004682345" ixy="-1.05438e-05" ixz="7.24398e-05" iyy="0.0002635246" iyz="1.6904e-06" izz="0.0003763351"/>
    </inertial>
    <visual>
      <origin rpy="0.0 0.0 0.0" xyz="0.0 0 0.0"/>
      <geometry>
        <mesh filename="package://centauro/centauro_urdf/meshes/simplified/velodyne.stl" scale="0.001 0.001 0.001"/>
      </geometry>
    </visual>
    <collision>
      <origin rpy="0.0 0.0 0.0" xyz="0.0 0 0.0"/>
      <geometry>
        <mesh filename="package://centauro/centauro_urdf/meshes/convex_hull/velodyne.stl" scale="0.001 0.001 0.001"/>
      </geometry>
    </collision>
  </link>
  <!-- /head links -->
  <!-- sensors links -->
  <link name="camera_central">
    <inertial>
      <origin xyz="0.0 0.0 0.0"/>
      <mass value="0.1"/>
      <inertia ixx="1e-06" ixy="0.0" ixz="0.0" iyy="1e-06" iyz="0.0" izz="1e-06"/>
    </inertial>
  </link>
  <link name="camera_left">
    <inertial>
      <origin xyz="0.0 0.0 0.0"/>
      <mass value="0.1"/>
      <inertia ixx="1e-06" ixy="0.0" ixz="0.0" iyy="1e-06" iyz="0.0" izz="1e-06"/>
    </inertial>
  </link>
  <link name="camera_right">
    <inertial>
      <origin xyz="0.0 0.0 0.0"/>
      <mass value="0.1"/>
      <inertia ixx="1e-06" ixy="0.0" ixz="0.0" iyy="1e-06" iyz="0.0" izz="1e-06"/>
    </inertial>
  </link>
  <link name="kinect">
    <inertial>
      <origin xyz="0.0 0.0 0.0"/>
      <mass value="0.1"/>
      <inertia ixx="1e-06" ixy="0.0" ixz="0.0" iyy="1e-06" iyz="0.0" izz="1e-06"/>
    </inertial>
  </link>
  <link name="kinect2_rgb_optical_frame"/>
  <link name="velodyne_mount">
    <inertial>
      <origin xyz="0.0 0.0 0.0"/>
      <mass value="0.1"/>
      <inertia ixx="1e-06" ixy="0.0" ixz="0.0" iyy="1e-06" iyz="0.0" izz="1e-06"/>
    </inertial>
  </link>
  <!-- /sensors links -->
  <!-- head joints -->
  <joint name="neck_yaw" type="revolute">
    <parent link="torso_2"/>
    <origin xyz="0.0 0.0 0.2795"/>
    <child link="neck_1"/>
    <axis xyz="0 0 1"/>
    <limit effort="35" lower="-0.78539816" upper="0.78539816" velocity="5.7"/>
    <!-- TODO -->
  </joint>
  <joint name="neck_pitch" type="revolute">
    <parent link="neck_1"/>
    <origin xyz="0.054 0.0596 -0.0124975"/>
    <child link="neck_2"/>
    <axis xyz="0 1 0"/>
    <limit effort="35" lower="-0.34906585" upper="0.78539816" velocity="5.7"/>
    <!-- TODO -->
  </joint>
  <joint name="neck_velodyne" type="continuous">
    <parent link="torso_2"/>
    <origin xyz="0.055 0.0 0.473262"/>
    <child link="neck_3"/>
    <axis xyz="0 0 1"/>
    <limit effort="35" velocity="5.7"/>
    <!-- TODO -->
  </joint>
  <!-- /head joints -->
  <!-- sensors transformations  -->
  <joint name="j_camera_central" type="fixed">
    <parent link="torso_2"/>
    <origin rpy="0.0 0.349065586018 0.0" xyz="0.0559593 5e-12 0.390626"/>
    <child link="camera_central"/>
  </joint>
  <joint name="j_camera_left" type="fixed">
    <parent link="torso_2"/>
    <origin rpy="0.0 0.349065586018 1.2217302006" xyz="0.0191392 0.0525845 0.390626"/>
    <child link="camera_left"/>
  </joint>
  <joint name="j_camera_right" type="fixed">
    <parent link="torso_2"/>
    <origin rpy="0.0 0.349065586018 -1.2217302006" xyz="0.0191392 -0.0525845 0.390626"/>
    <child link="camera_right"/>
  </joint>
  <joint name="j_kinect" type="fixed">
    <parent link="neck_2"/>
    <origin rpy="0.0 0.0 0.0" xyz="0.03 -0.0596 0.045855"/>
    <child link="kinect"/>
  </joint>
  <joint name="j_kinect_optical_frame" type="fixed">
    <parent link="kinect"/>
    <child link="kinect2_rgb_optical_frame"/>
    <origin rpy=" -1.5707963268 0 -1.5707963268" xyz="0.050 -0.110 -0.035"/>
  </joint>
  <joint name="j_velodyne" type="fixed">
    <parent link="neck_3"/>
    <origin rpy="0.0 0.0 -3.14159265359" xyz="-0.138 0.0 -0.033"/>
    <child link="velodyne_mount"/>
  </joint>
  <!-- /sensors transformations -->
  <transmission name="t_neck_yaw">
    <type> transmission_interface/SimpleTransmission</type>
    <joint name="neck_yaw">
      <hardwareInterface>hardware_interface/EffortJointInterface</hardwareInterface>
    </joint>
    <actuator name="motor_neck_yaw">
      <hardwareInterface>hardware_interface/EffortJointInterface</hardwareInterface>
      <machanicalReduction>1</machanicalReduction>
    </actuator>
    <robotNamespace>/centauro</robotNamespace>
  </transmission>
  <transmission name="t_neck_pitch">
    <type> transmission_interface/SimpleTransmission</type>
    <joint name="neck_pitch">
      <hardwareInterface>hardware_interface/EffortJointInterface</hardwareInterface>
    </joint>
    <actuator name="motor_neck_pitch">
      <hardwareInterface>hardware_interface/EffortJointInterface</hardwareInterface>
      <machanicalReduction>1</machanicalReduction>
    </actuator>
    <robotNamespace>/centauro</robotNamespace>
  </transmission>
  <transmission name="t_neck_velodyne">
    <type> transmission_interface/SimpleTransmission</type>
    <joint name="neck_velodyne">
      <hardwareInterface>hardware_interface/EffortJointInterface</hardwareInterface>
    </joint>
    <actuator name="motor_neck_velodyne">
      <hardwareInterface>hardware_interface/EffortJointInterface</hardwareInterface>
      <machanicalReduction>1</machanicalReduction>
    </actuator>
    <robotNamespace>/centauro</robotNamespace>
  </transmission>
  <!-- /torso actuators -->
  <!-- /torso -->
  <!-- LINKS -->
  <!-- shoulder yaw-roll-->
  <link name="arm1_1">
    <inertial>
      <origin xyz="-0.0031005886 0.040324584 0.007451937"/>
      <mass value="1.5583338"/>
      <inertia ixx="0.0032318636" ixy="4.24587e-05" ixz="4.91626e-05" iyy="0.00275718" iyz="-0.0002387056" izz="0.004275047"/>
    </inertial>
    <visual>
      <origin rpy="0.0 0.0 0.0" xyz="0.0 0.0 0.0"/>
      <geometry>
        <mesh filename="package://centauro/centauro_urdf/meshes/simplified/link2.stl" scale="0.001 -0.001 0.001"/>
      </geometry>
      <material name="dark_grey"/>
    </visual>
    <collision>
      <origin rpy="0.0 0.0 0.0" xyz="0.0 0.0 0.0"/>
      <geometry>
        <mesh filename="package://centauro/centauro_urdf/meshes/convex_hull/link2.stl" scale="0.001 -0.001 0.001"/>
      </geometry>
    </collision>
  </link>
  <!-- shoulder yaw-roll-->
  <!-- shoulder roll-pitch-->
  <link name="arm1_2">
    <inertial>
      <origin xyz="0.05105435 0.00011109 -0.07643596"/>
      <mass value="1.515061"/>
      <inertia ixx="0.01029558" ixy="2.846e-05" ixz="0.0036567" iyy="0.01178018" iyz="2.088e-05" izz="0.00386123"/>
    </inertial>
    <visual>
      <origin rpy="0.0 0.0 0.0" xyz="0.0 0.0 0.0"/>
      <geometry>
        <mesh filename="package://centauro/centauro_urdf/meshes/simplified/link3.stl" scale="0.001 -0.001 0.001"/>
      </geometry>
    </visual>
    <collision>
      <origin rpy="0.0 0.0 0.0" xyz="0.0 0.0 0.0"/>
      <geometry>
        <mesh filename="package://centauro/centauro_urdf/meshes/convex_hull/link3.stl" scale="0.001 -0.001 0.001"/>
      </geometry>
    </collision>
  </link>
  <!-- shoulder roll-pitch-->
  <!-- shoulder-elbow -->
  <link name="arm1_3">
    <inertial>
      <origin xyz="0.01207624 0.00322013 -0.03427312"/>
      <mass value="1.5088101"/>
      <inertia ixx="0.00469819" ixy="-0.00026547" ixz="0.00077706" iyy="0.00501755" iyz="0.00029679" izz="0.00310954"/>
    </inertial>
    <visual>
      <origin rpy="0.0 0.0 0.0" xyz="0.0 0.0 0.0"/>
      <geometry>
        <mesh filename="package://centauro/centauro_urdf/meshes/simplified/link4.stl" scale="0.001 -0.001 0.001"/>
      </geometry>
      <material name="dark_grey"/>
    </visual>
    <collision>
      <origin rpy="0.0 0.0 0.0" xyz="0.0 0.0 0.0"/>
      <geometry>
        <mesh filename="package://centauro/centauro_urdf/meshes/convex_hull/link4.stl" scale="0.001 -0.001 0.001"/>
      </geometry>
    </collision>
  </link>
  <!-- /shoulder-elbow -->
  <!-- elbow yaw-pitch -->
  <link name="arm1_4">
    <inertial>
      <origin xyz="0.010147552 -0.029928537 -0.032528288"/>
      <mass value="0.96297329"/>
      <inertia ixx="0.0026493567" ixy="5.1632e-06" ixz="0.0001292309" iyy="0.0023470955" iyz="-0.0007895755" izz="0.0012213063"/>
    </inertial>
    <visual>
      <origin rpy="0.0 0.0 0.0" xyz="0.0 0.0 0.0"/>
      <geometry>
        <mesh filename="package://centauro/centauro_urdf/meshes/simplified/link5.stl" scale="0.001 -0.001 0.001"/>
      </geometry>
    </visual>
    <collision>
      <origin rpy="0.0 0.0 0.0" xyz="0.0 0.0 0.0"/>
      <geometry>
        <mesh filename="package://centauro/centauro_urdf/meshes/convex_hull/link5.stl" scale="0.001 -0.001 0.001"/>
      </geometry>
    </collision>
  </link>
  <!-- /elbow yaw-pitch -->
  <!-- elbow-wrist -->
  <link name="arm1_5">
    <inertial>
      <origin xyz="-0.0001574443 0.0041320907 -0.10756614"/>
      <mass value="1.4703698"/>
      <inertia ixx="0.0064160453" ixy="1.96382e-05" ixz="2.49912e-05" iyy="0.0062016367" iyz="-0.0001987903" izz="0.0017091658"/>
    </inertial>
    <visual>
      <origin rpy="0.0 0.0 0.0" xyz="0.0 0.0 0.0"/>
      <geometry>
        <mesh filename="package://centauro/centauro_urdf/meshes/simplified/link6.stl" scale="0.001 -0.001 0.001"/>
      </geometry>
      <material name="dark_grey"/>
    </visual>
    <collision>
      <origin rpy="0.0 0.0 0.0" xyz="0.0 0.0 0.0"/>
      <geometry>
        <mesh filename="package://centauro/centauro_urdf/meshes/convex_hull/link6.stl" scale="0.001 -0.001 0.001"/>
      </geometry>
    </collision>
  </link>
  <!-- /elbow-wrist -->
  <!-- wrist yaw-pitch -->
  <link name="arm1_6">
    <inertial>
      <origin xyz="3.23645e-05 -0.035947237 -0.080878061"/>
      <mass value="0.94693868"/>
      <inertia ixx="0.0036896582" ixy="2.63667e-05" ixz="1.4005e-06" iyy="0.0034146283" iyz="-0.0008268103" izz="0.0010790183"/>
    </inertial>
    <visual>
      <origin rpy="0.0 0.0 0.0" xyz="0.0 0.0 0.0"/>
      <geometry>
        <mesh filename="package://centauro/centauro_urdf/meshes/simplified/link7.stl" scale="0.001 -0.001 0.001"/>
      </geometry>
    </visual>
    <collision>
      <origin rpy="0.0 0.0 0.0" xyz="0.0 0.0 0.0"/>
      <geometry>
        <mesh filename="package://centauro/centauro_urdf/meshes/convex_hull/link7.stl" scale="0.001 -0.001 0.001"/>
      </geometry>
    </collision>
  </link>
  <!-- /wrist yaw-pitch -->
  <link name="arm1_7">
    <inertial>
      <origin xyz="2.46596e-05 -0.0001467705 -0.0052993013"/>
      <mass value="0.55981036"/>
      <inertia ixx="0.0004360175" ixy="1.397e-07" ixz="-1.382e-07" iyy="0.0004299166" iyz="-1.4752e-06" izz="0.0004522224"/>
    </inertial>
    <visual>
      <origin rpy="0.0 0.0 0.0" xyz="0.0 0.0 0.0"/>
      <geometry>
        <mesh filename="package://centauro/centauro_urdf/meshes/simplified/link8.stl" scale="0.001 -0.001 0.001"/>
      </geometry>
      <material name="dark_grey"/>
    </visual>
    <collision>
      <origin rpy="0.0 0.0 0.0" xyz="0.0 0.0 0.0"/>
      <geometry>
        <mesh filename="package://centauro/centauro_urdf/meshes/convex_hull/link8.stl" scale="0.001 -0.001 0.001"/>
      </geometry>
    </collision>
  </link>
  <!-- /LINKS -->
  <!-- JOINTS -->
  <!-- shoulder yaw -->
  <joint name="j_arm1_1" type="revolute">
    <parent link="torso_2"/>
    <child link="arm1_1"/>
    <origin rpy="0.0 0.0 -0.523602668986" xyz="0.04576 0.169137 0.116626"/>
    <axis xyz="0 0.984807753012 0.173648177667"/>
    <limit effort="147" lower="-3.348" upper="1.578" velocity="5.7"/>
  </joint>
  <!-- /shoulder yaw -->
  <!-- shoulder roll -->
  <joint name="j_arm1_2" type="revolute">
    <parent link="arm1_1"/>
    <child link="arm1_2"/>
    <origin xyz="-0.09115 0.06106 0.010766"/>
    <axis xyz="-1 0 0"/>
    <limit effort="147" lower="-3.42" upper="-0.056" velocity="5.7"/>
  </joint>
  <!-- /shoulder roll -->
  <!-- shoulder pitch-->
  <joint name="j_arm1_3" type="revolute">
    <parent link="arm1_2"/>
    <child link="arm1_3"/>
    <origin xyz="0.09115 0.0 -0.21915"/>
    <axis xyz="0 0 -1"/>
    <limit effort="147" lower="-2.5556" upper="2.5424" velocity="8.2"/>
  </joint>
  <!-- /shoulder pitch -->
  <!-- elbow yaw -->
  <joint name="j_arm1_4" type="revolute">
    <parent link="arm1_3"/>
    <child link="arm1_4"/>
    <origin xyz="0.04 0.05615 -0.074"/>
    <axis xyz="0 1 0"/>
    <limit effort="147" lower="-2.4636" upper="0.2804" velocity="8.2"/>
  </joint>
  <!-- /elbow yaw -->
  <!-- elbow pitch-->
  <joint name="j_arm1_5" type="revolute">
    <parent link="arm1_4"/>
    <child link="arm1_5"/>
    <origin xyz="-0.015 -0.05615 -0.061"/>
    <axis xyz="0 0 -1"/>
    <limit effort="55" lower="-2.5406" upper="2.5534" velocity="11.6"/>
  </joint>
  <!-- /elbow pitch-->
  <!-- wrist yaw-->
  <joint name="j_arm1_6" type="revolute">
    <parent link="arm1_5"/>
    <child link="arm1_6"/>
    <origin xyz="0.0 0.049 -0.18"/>
    <axis xyz="0 1 0"/>
    <limit effort="55" lower="-1.5096" upper="1.5044" velocity="11.6"/>
  </joint>
  <!-- /wrist yaw-->
  <!-- wrist pitch-->
  <joint name="j_arm1_7" type="revolute">
    <parent link="arm1_6"/>
    <child link="arm1_7"/>
    <origin xyz="0.0 -0.049 -0.169"/>
    <axis xyz="0 0 -1"/>
    <limit effort="27" lower="-2.5376" upper="2.5554" velocity="20.3"/>
  </joint>
  <!-- wrist pitch-->
  <!-- force-troque sensor -->
  <transmission name="t_j_arm1_1">
    <type> transmission_interface/SimpleTransmission</type>
    <joint name="j_arm1_1">
      <hardwareInterface>hardware_interface/EffortJointInterface</hardwareInterface>
    </joint>
    <actuator name="motor_j_arm1_1">
      <hardwareInterface>hardware_interface/EffortJointInterface</hardwareInterface>
      <machanicalReduction>1</machanicalReduction>
    </actuator>
    <robotNamespace>/centauro</robotNamespace>
  </transmission>
  <transmission name="t_j_arm1_2">
    <type> transmission_interface/SimpleTransmission</type>
    <joint name="j_arm1_2">
      <hardwareInterface>hardware_interface/EffortJointInterface</hardwareInterface>
    </joint>
    <actuator name="motor_j_arm1_2">
      <hardwareInterface>hardware_interface/EffortJointInterface</hardwareInterface>
      <machanicalReduction>1</machanicalReduction>
    </actuator>
    <robotNamespace>/centauro</robotNamespace>
  </transmission>
  <transmission name="t_j_arm1_3">
    <type> transmission_interface/SimpleTransmission</type>
    <joint name="j_arm1_3">
      <hardwareInterface>hardware_interface/EffortJointInterface</hardwareInterface>
    </joint>
    <actuator name="motor_j_arm1_3">
      <hardwareInterface>hardware_interface/EffortJointInterface</hardwareInterface>
      <machanicalReduction>1</machanicalReduction>
    </actuator>
    <robotNamespace>/centauro</robotNamespace>
  </transmission>
  <transmission name="t_j_arm1_4">
    <type> transmission_interface/SimpleTransmission</type>
    <joint name="j_arm1_4">
      <hardwareInterface>hardware_interface/EffortJointInterface</hardwareInterface>
    </joint>
    <actuator name="motor_j_arm1_4">
      <hardwareInterface>hardware_interface/EffortJointInterface</hardwareInterface>
      <machanicalReduction>1</machanicalReduction>
    </actuator>
    <robotNamespace>/centauro</robotNamespace>
  </transmission>
  <transmission name="t_j_arm1_5">
    <type> transmission_interface/SimpleTransmission</type>
    <joint name="j_arm1_5">
      <hardwareInterface>hardware_interface/EffortJointInterface</hardwareInterface>
    </joint>
    <actuator name="motor_j_arm1_5">
      <hardwareInterface>hardware_interface/EffortJointInterface</hardwareInterface>
      <machanicalReduction>1</machanicalReduction>
    </actuator>
    <robotNamespace>/centauro</robotNamespace>
  </transmission>
  <transmission name="t_j_arm1_6">
    <type> transmission_interface/SimpleTransmission</type>
    <joint name="j_arm1_6">
      <hardwareInterface>hardware_interface/EffortJointInterface</hardwareInterface>
    </joint>
    <actuator name="motor_j_arm1_6">
      <hardwareInterface>hardware_interface/EffortJointInterface</hardwareInterface>
      <machanicalReduction>1</machanicalReduction>
    </actuator>
    <robotNamespace>/centauro</robotNamespace>
  </transmission>
  <transmission name="t_j_arm1_7">
    <type> transmission_interface/SimpleTransmission</type>
    <joint name="j_arm1_7">
      <hardwareInterface>hardware_interface/EffortJointInterface</hardwareInterface>
    </joint>
    <actuator name="motor_j_arm1_7">
      <hardwareInterface>hardware_interface/EffortJointInterface</hardwareInterface>
      <machanicalReduction>1</machanicalReduction>
    </actuator>
    <robotNamespace>/centauro</robotNamespace>
  </transmission>
  <!-- /actuators -->
  <!-- links -->
  <link name="arm1_8">
    <inertial>
      <origin rpy="0 0 0" xyz="0.001 0.0 0.006"/>
      <mass value="0.15"/>
      <inertia ixx="0.0002" ixy="0.0" ixz="0.0" iyy="0.0002" iyz="0.0" izz="1e-05"/>
      <!--          <inertia ixx="0.003"  ixy="0"  ixz="0" iyy="0.0025" iyz="0" izz="0.00016900" /> -->
    </inertial>
    <visual>
      <origin rpy="0.0 0.0 0.0" xyz="0.0 0.0 0.0"/>
      <geometry>
        <mesh filename="package://centauro/centauro_urdf/meshes/simplified/link9.stl" scale="0.001 -0.001 -0.001"/>
      </geometry>
      <material name="dark_grey"/>
    </visual>
    <collision>
      <origin rpy="0.0 0.0 0.0" xyz="0.0 0.0 0.0"/>
      <geometry>
        <mesh filename="package://centauro/centauro_urdf/meshes/convex_hull/link9.stl" scale="0.001 -0.001 -0.001"/>
      </geometry>
    </collision>
  </link>
  <!-- /links -->
  <!-- joints -->
  <joint name="j_arm1_8" type="fixed">
    <parent link="arm1_7"/>
    <origin rpy="0.0 3.14159265359 -1.5707963268" xyz="0.0 0.0 -0.0405"/>
    <child link="arm1_8"/>
    <axis xyz="1 0 0"/>
  </joint>
   --&gt;

  <!-- /joints -->
  <!-- /end-effector -->
  <!-- LINKS -->
  <!-- shoulder yaw-roll-->
  <link name="arm2_1">
    <inertial>
      <origin xyz="-0.0031005886 -0.040324584 0.007451937"/>
      <mass value="1.5583338"/>
      <inertia ixx="0.0032318636" ixy="-4.24587e-05" ixz="4.91626e-05" iyy="0.00275718" iyz="0.0002387056" izz="0.004275047"/>
    </inertial>
    <visual>
      <origin rpy="0.0 0.0 0.0" xyz="0.0 0.0 0.0"/>
      <geometry>
        <mesh filename="package://centauro/centauro_urdf/meshes/simplified/link2.stl" scale="0.001 0.001 0.001"/>
      </geometry>
      <material name="dark_grey"/>
    </visual>
    <collision>
      <origin rpy="0.0 0.0 0.0" xyz="0.0 0.0 0.0"/>
      <geometry>
        <mesh filename="package://centauro/centauro_urdf/meshes/convex_hull/link2.stl" scale="0.001 0.001 0.001"/>
      </geometry>
    </collision>
  </link>
  <!-- shoulder yaw-roll-->
  <!-- shoulder roll-pitch-->
  <link name="arm2_2">
    <inertial>
      <origin xyz="0.05105435 -0.00011109 -0.07643596"/>
      <mass value="1.515061"/>
      <inertia ixx="0.01029558" ixy="-2.846e-05" ixz="0.0036567" iyy="0.01178018" iyz="-2.088e-05" izz="0.00386123"/>
    </inertial>
    <visual>
      <origin rpy="0.0 0.0 0.0" xyz="0.0 0.0 0.0"/>
      <geometry>
        <mesh filename="package://centauro/centauro_urdf/meshes/simplified/link3.stl" scale="0.001 0.001 0.001"/>
      </geometry>
    </visual>
    <collision>
      <origin rpy="0.0 0.0 0.0" xyz="0.0 0.0 0.0"/>
      <geometry>
        <mesh filename="package://centauro/centauro_urdf/meshes/convex_hull/link3.stl" scale="0.001 0.001 0.001"/>
      </geometry>
    </collision>
  </link>
  <!-- shoulder roll-pitch-->
  <!-- shoulder-elbow -->
  <link name="arm2_3">
    <inertial>
      <origin xyz="0.01207624 -0.00322013 -0.03427312"/>
      <mass value="1.5088101"/>
      <inertia ixx="0.00469819" ixy="0.00026547" ixz="0.00077706" iyy="0.00501755" iyz="-0.00029679" izz="0.00310954"/>
    </inertial>
    <visual>
      <origin rpy="0.0 0.0 0.0" xyz="0.0 0.0 0.0"/>
      <geometry>
        <mesh filename="package://centauro/centauro_urdf/meshes/simplified/link4.stl" scale="0.001 0.001 0.001"/>
      </geometry>
      <material name="dark_grey"/>
    </visual>
    <collision>
      <origin rpy="0.0 0.0 0.0" xyz="0.0 0.0 0.0"/>
      <geometry>
        <mesh filename="package://centauro/centauro_urdf/meshes/convex_hull/link4.stl" scale="0.001 0.001 0.001"/>
      </geometry>
    </collision>
  </link>
  <!-- /shoulder-elbow -->
  <!-- elbow yaw-pitch -->
  <link name="arm2_4">
    <inertial>
      <origin xyz="0.010147552 0.029928537 -0.032528288"/>
      <mass value="0.96297329"/>
      <inertia ixx="0.0026493567" ixy="-5.1632e-06" ixz="0.0001292309" iyy="0.0023470955" iyz="0.0007895755" izz="0.0012213063"/>
    </inertial>
    <visual>
      <origin rpy="0.0 0.0 0.0" xyz="0.0 0.0 0.0"/>
      <geometry>
        <mesh filename="package://centauro/centauro_urdf/meshes/simplified/link5.stl" scale="0.001 0.001 0.001"/>
      </geometry>
    </visual>
    <collision>
      <origin rpy="0.0 0.0 0.0" xyz="0.0 0.0 0.0"/>
      <geometry>
        <mesh filename="package://centauro/centauro_urdf/meshes/convex_hull/link5.stl" scale="0.001 0.001 0.001"/>
      </geometry>
    </collision>
  </link>
  <!-- /elbow yaw-pitch -->
  <!-- elbow-wrist -->
  <link name="arm2_5">
    <inertial>
      <origin xyz="-0.0001574443 -0.0041320907 -0.10756614"/>
      <mass value="1.4703698"/>
      <inertia ixx="0.0064160453" ixy="-1.96382e-05" ixz="2.49912e-05" iyy="0.0062016367" iyz="0.0001987903" izz="0.0017091658"/>
    </inertial>
    <visual>
      <origin rpy="0.0 0.0 0.0" xyz="0.0 0.0 0.0"/>
      <geometry>
        <mesh filename="package://centauro/centauro_urdf/meshes/simplified/link6.stl" scale="0.001 0.001 0.001"/>
      </geometry>
      <material name="dark_grey"/>
    </visual>
    <collision>
      <origin rpy="0.0 0.0 0.0" xyz="0.0 0.0 0.0"/>
      <geometry>
        <mesh filename="package://centauro/centauro_urdf/meshes/convex_hull/link6.stl" scale="0.001 0.001 0.001"/>
      </geometry>
    </collision>
  </link>
  <!-- /elbow-wrist -->
  <!-- wrist yaw-pitch -->
  <link name="arm2_6">
    <inertial>
      <origin xyz="3.23645e-05 0.035947237 -0.080878061"/>
      <mass value="0.94693868"/>
      <inertia ixx="0.0036896582" ixy="-2.63667e-05" ixz="1.4005e-06" iyy="0.0034146283" iyz="0.0008268103" izz="0.0010790183"/>
    </inertial>
    <visual>
      <origin rpy="0.0 0.0 0.0" xyz="0.0 0.0 0.0"/>
      <geometry>
        <mesh filename="package://centauro/centauro_urdf/meshes/simplified/link7.stl" scale="0.001 0.001 0.001"/>
      </geometry>
    </visual>
    <collision>
      <origin rpy="0.0 0.0 0.0" xyz="0.0 0.0 0.0"/>
      <geometry>
        <mesh filename="package://centauro/centauro_urdf/meshes/convex_hull/link7.stl" scale="0.001 0.001 0.001"/>
      </geometry>
    </collision>
  </link>
  <!-- /wrist yaw-pitch -->
  <link name="arm2_7">
    <inertial>
      <origin xyz="2.46596e-05 0.0001467705 -0.0052993013"/>
      <mass value="0.55981036"/>
      <inertia ixx="0.0004360175" ixy="-1.397e-07" ixz="-1.382e-07" iyy="0.0004299166" iyz="1.4752e-06" izz="0.0004522224"/>
    </inertial>
    <visual>
      <origin rpy="0.0 0.0 0.0" xyz="0.0 0.0 0.0"/>
      <geometry>
        <mesh filename="package://centauro/centauro_urdf/meshes/simplified/link8.stl" scale="0.001 0.001 0.001"/>
      </geometry>
      <material name="dark_grey"/>
    </visual>
    <collision>
      <origin rpy="0.0 0.0 0.0" xyz="0.0 0.0 0.0"/>
      <geometry>
        <mesh filename="package://centauro/centauro_urdf/meshes/convex_hull/link8.stl" scale="0.001 0.001 0.001"/>
      </geometry>
    </collision>
  </link>
  <!-- /LINKS -->
  <!-- JOINTS -->
  <!-- shoulder yaw -->
  <joint name="j_arm2_1" type="revolute">
    <parent link="torso_2"/>
    <child link="arm2_1"/>
    <origin rpy="0.0 0.0 0.523602668986" xyz="0.04576 -0.169137 0.116626"/>
    <axis xyz="0 -0.984807753012 0.173648177667"/>
    <limit effort="147" lower="-1.6102" upper="3.3138" velocity="5.7"/>
  </joint>
  <!-- /shoulder yaw -->
  <!-- shoulder roll -->
  <joint name="j_arm2_2" type="revolute">
    <parent link="arm2_1"/>
    <child link="arm2_2"/>
    <origin xyz="-0.09115 -0.06106 0.010766"/>
    <axis xyz="-1 0 0"/>
    <limit effort="147" lower="0.0578" upper="3.4288" velocity="5.7"/>
  </joint>
  <!-- /shoulder roll -->
  <!-- shoulder pitch-->
  <joint name="j_arm2_3" type="revolute">
    <parent link="arm2_2"/>
    <child link="arm2_3"/>
    <origin xyz="0.09115 0.0 -0.21915"/>
    <axis xyz="0 0 -1"/>
    <limit effort="147" lower="-2.5426" upper="2.5524" velocity="8.2"/>
  </joint>
  <!-- /shoulder pitch -->
  <!-- elbow yaw -->
  <joint name="j_arm2_4" type="revolute">
    <parent link="arm2_3"/>
    <child link="arm2_4"/>
    <origin xyz="0.04 -0.05615 -0.074"/>
    <axis xyz="0 -1 0"/>
    <limit effort="147" lower="-0.2796" upper="2.4564" velocity="8.2"/>
  </joint>
  <!-- /elbow yaw -->
  <!-- elbow pitch-->
  <joint name="j_arm2_5" type="revolute">
    <parent link="arm2_4"/>
    <child link="arm2_5"/>
    <origin xyz="-0.015 0.05615 -0.061"/>
    <axis xyz="0 0 -1"/>
    <limit effort="55" lower="-2.5626" upper="2.5464" velocity="11.6"/>
  </joint>
  <!-- /elbow pitch-->
  <!-- wrist yaw-->
  <joint name="j_arm2_6" type="revolute">
    <parent link="arm2_5"/>
    <child link="arm2_6"/>
    <origin xyz="0.0 -0.049 -0.18"/>
    <axis xyz="0 -1 0"/>
    <limit effort="55" lower="-1.4726" upper="1.5364" velocity="11.6"/>
  </joint>
  <!-- /wrist yaw-->
  <!-- wrist pitch-->
  <joint name="j_arm2_7" type="revolute">
    <parent link="arm2_6"/>
    <child link="arm2_7"/>
    <origin xyz="0.0 0.049 -0.169"/>
    <axis xyz="0 0 -1"/>
    <limit effort="27" lower="-3.0908" upper="2.0114" velocity="20.3"/>
  </joint>
  <!-- wrist pitch-->
  <!-- force-troque sensor -->
  <transmission name="t_j_arm2_1">
    <type> transmission_interface/SimpleTransmission</type>
    <joint name="j_arm2_1">
      <hardwareInterface>hardware_interface/EffortJointInterface</hardwareInterface>
    </joint>
    <actuator name="motor_j_arm2_1">
      <hardwareInterface>hardware_interface/EffortJointInterface</hardwareInterface>
      <machanicalReduction>1</machanicalReduction>
    </actuator>
    <robotNamespace>/centauro</robotNamespace>
  </transmission>
  <transmission name="t_j_arm2_2">
    <type> transmission_interface/SimpleTransmission</type>
    <joint name="j_arm2_2">
      <hardwareInterface>hardware_interface/EffortJointInterface</hardwareInterface>
    </joint>
    <actuator name="motor_j_arm2_2">
      <hardwareInterface>hardware_interface/EffortJointInterface</hardwareInterface>
      <machanicalReduction>1</machanicalReduction>
    </actuator>
    <robotNamespace>/centauro</robotNamespace>
  </transmission>
  <transmission name="t_j_arm2_3">
    <type> transmission_interface/SimpleTransmission</type>
    <joint name="j_arm2_3">
      <hardwareInterface>hardware_interface/EffortJointInterface</hardwareInterface>
    </joint>
    <actuator name="motor_j_arm2_3">
      <hardwareInterface>hardware_interface/EffortJointInterface</hardwareInterface>
      <machanicalReduction>1</machanicalReduction>
    </actuator>
    <robotNamespace>/centauro</robotNamespace>
  </transmission>
  <transmission name="t_j_arm2_4">
    <type> transmission_interface/SimpleTransmission</type>
    <joint name="j_arm2_4">
      <hardwareInterface>hardware_interface/EffortJointInterface</hardwareInterface>
    </joint>
    <actuator name="motor_j_arm2_4">
      <hardwareInterface>hardware_interface/EffortJointInterface</hardwareInterface>
      <machanicalReduction>1</machanicalReduction>
    </actuator>
    <robotNamespace>/centauro</robotNamespace>
  </transmission>
  <transmission name="t_j_arm2_5">
    <type> transmission_interface/SimpleTransmission</type>
    <joint name="j_arm2_5">
      <hardwareInterface>hardware_interface/EffortJointInterface</hardwareInterface>
    </joint>
    <actuator name="motor_j_arm2_5">
      <hardwareInterface>hardware_interface/EffortJointInterface</hardwareInterface>
      <machanicalReduction>1</machanicalReduction>
    </actuator>
    <robotNamespace>/centauro</robotNamespace>
  </transmission>
  <transmission name="t_j_arm2_6">
    <type> transmission_interface/SimpleTransmission</type>
    <joint name="j_arm2_6">
      <hardwareInterface>hardware_interface/EffortJointInterface</hardwareInterface>
    </joint>
    <actuator name="motor_j_arm2_6">
      <hardwareInterface>hardware_interface/EffortJointInterface</hardwareInterface>
      <machanicalReduction>1</machanicalReduction>
    </actuator>
    <robotNamespace>/centauro</robotNamespace>
  </transmission>
  <transmission name="t_j_arm2_7">
    <type> transmission_interface/SimpleTransmission</type>
    <joint name="j_arm2_7">
      <hardwareInterface>hardware_interface/EffortJointInterface</hardwareInterface>
    </joint>
    <actuator name="motor_j_arm2_7">
      <hardwareInterface>hardware_interface/EffortJointInterface</hardwareInterface>
      <machanicalReduction>1</machanicalReduction>
    </actuator>
    <robotNamespace>/centauro</robotNamespace>
  </transmission>
  <!-- /actuators -->
  <!-- links -->
  <link name="arm2_8">
    <inertial>
      <origin rpy="0 0 0" xyz="0.001 0.0 0.006"/>
      <mass value="0.15"/>
      <inertia ixx="0.0002" ixy="0.0" ixz="0.0" iyy="0.0002" iyz="0.0" izz="1e-05"/>
      <!--          <inertia ixx="0.003"  ixy="0"  ixz="0" iyy="0.0025" iyz="0" izz="0.00016900" /> -->
    </inertial>
    <visual>
      <origin rpy="0.0 0.0 0.0" xyz="0.0 0.0 0.0"/>
      <geometry>
        <mesh filename="package://centauro/centauro_urdf/meshes/simplified/link9.stl" scale="0.001 0.001 -0.001"/>
      </geometry>
      <material name="dark_grey"/>
    </visual>
    <collision>
      <origin rpy="0.0 0.0 0.0" xyz="0.0 0.0 0.0"/>
      <geometry>
        <mesh filename="package://centauro/centauro_urdf/meshes/convex_hull/link9.stl" scale="0.001 0.001 -0.001"/>
      </geometry>
    </collision>
  </link>
  <!-- /links -->
  <!-- joints -->
  <joint name="j_arm2_8" type="fixed">
    <parent link="arm2_7"/>
    <origin rpy="0.0 3.14159265359 -1.5707963268" xyz="0.0 0.0 -0.0405"/>
    <child link="arm2_8"/>
    <axis xyz="1 0 0"/>
  </joint>
   --&gt;

  <!-- /joints -->
  <!-- /end-effector -->
  <!-- /arms -->
  <!-- /legs -->
</robot>
